Algunas veces abstraemos la lógica de nuestras peticiones HTTP en funciones asíncronas que utilizan internamente la *fetch API*.
### Petición exitosa

Obtenemos la variables de entorno (si es necesario):

```
const { baseUrl, token } = environment;
const issueId = '123';
const issueResp = {
  id: 123,
  name: '# Fake Issue',
};
```

Definimos el *endpoint* de nuestra API al cual se realizará nuestra petición y creamos una respuesta del servidor ficticia:

```
const url = `${baseUrl}/issues/${issueId}`;
const response = new Response(JSON.stringify(issueResp), {
  status: 200,
  statusText: 'Ok',
});
```

Agregamos un espía sobre la función *fetch* y adjuntamos la respuesta ficticia:

```
spyOn(window, 'fetch').and.resolveTo(response);
```

Ejecutamos la petición:

```
await getIssue(issueId);
```

Verificamos que la petición se haya realizado sobre el *endpoint* correcto, con el *token* de autenticación y que haya sido ejecutada una sola vez:

```
expect(window.fetch).toHaveBeenCalledOnceWith(url, {
  headers: {
    Authorization: `Bearer ${token}`,
  },
});
```
### Petición fallida

Para validar un error en la petición podemos reutilizar gran parte de la estructura que utilizamos para validar una exitosa.

Modificamos la respuesta del servidor ficticia:

```
const response = new Response(JSON.stringify(issueResp), {
  status: 400,
  statusText: 'Bad Request',
});
```

Dado que nuestra función dispara un error (*throw*) debemos envolver dicho proceso en un bloque *try-catch*:

```
try {
  await getIssue(issueId);
} catch (error) {
  expect(error).toBe(`Can't load issue info with id ${issueId}`);
}
```